Traceback (most recent call last):
  File "C:\Users\kuznetsov_as\AppData\Local\Programs\Python\Python37\lib\site-packages\pandas\core\indexes\base.py", line 3361, in get_loc
    return self._engine.get_loc(casted_key)
  File "pandas\_libs\index.pyx", line 76, in pandas._libs.index.IndexEngine.get_loc
  File "pandas\_libs\index.pyx", line 108, in pandas._libs.index.IndexEngine.get_loc
  File "pandas\_libs\hashtable_class_helper.pxi", line 5198, in pandas._libs.hashtable.PyObjectHashTable.get_item
  File "pandas\_libs\hashtable_class_helper.pxi", line 5206, in pandas._libs.hashtable.PyObjectHashTable.get_item
KeyError: 'Длительность звонка'

The above exception was the direct cause of the following exception:

Traceback (most recent call last):
  File "runner_test.py", line 66, in transform
    df['Длительность звонка'] = pd.to_timedelta(df['Длительность звонка'])
  File "C:\Users\kuznetsov_as\AppData\Local\Programs\Python\Python37\lib\site-packages\pandas\core\frame.py", line 3458, in __getitem__
    indexer = self.columns.get_loc(key)
  File "C:\Users\kuznetsov_as\AppData\Local\Programs\Python\Python37\lib\site-packages\pandas\core\indexes\base.py", line 3363, in get_loc
    raise KeyError(key) from err
KeyError: 'Длительность звонка'
